Workbook

Sheet HOW TO USE
C2: Steps | D2: By | E2: How often to update
B3: 1 | C3: Fill out list of Beneficiary Agencies you are serving, in the "Beneficiary Agency Database" sheet | E3: Update whenever you have a new Beneficiary Agency Review information with Beneficiary Agencies every year, and update the list with their latest information
B4: 2 | C4: Fill out list of Donors you are receiving donations from, in the "Food Donor Database" sheet | D4: Food Sourcing | E4: Update whenever you have a new Donor
B5: 3 | C5: Record all incoming donations in "Product In" sheet | D5: Operations | E5: Daily
B6: 4 | C6: Record all outgoing distributions in "Product Out" sheet | D6: Operations | E6: Daily

Sheet VIEW ONLY Dashboard
A1: Food Bank | B1: Cebu Food Bank | E1: DO NOT EDIT THIS SHEET. NUMBERS ARE AUTOMATICALLY DRAWN FROM THE 4 COLORED SHEETS.
A2: Month & Year | B2: 45597
A4: Product Sourcing
A20: Product Category | B20: Quantity | C20: % of Total | D20: Donor Category | E20: Quantity | F20: Donated/Purchased | G20: Quantity
A21: Bakery | B21: =SUMIF('Product In'!E:E,'VIEW ONLY Dashboard'!A21,'Product In'!I:I) -> 20.9 | C21: =B21/SUM($B$21:$B$41) -> 0.0027083765 | D21: Agriculture | E21: =SUMIF('Product In'!D:D,'VIEW ONLY Dashboard'!D21,'Product In'!I:I) -> 0 | F21: Donated | G21: =SUMIF('Product In'!L:L,'VIEW ONLY Dashboard'!F21,'Product In'!I:I) -> 7716.8
A22: Confectionary | B22: =SUMIF('Product In'!E:E,'VIEW ONLY Dashboard'!A22,'Product In'!I:I) -> 7.3 | C22: =B22/SUM($B$21:$B$41) -> 0.00094598797 | D22: Food Services | E22: =SUMIF('Product In'!D:D,'VIEW ONLY Dashboard'!D22,'Product In'!I:I) -> 0 | F22: Purchased | G22: =SUMIF('Product In'!L:L,'VIEW ONLY Dashboard'!F22,'Product In'!I:I) -> 0
A23: Dairy | B23: =SUMIF('Product In'!E:E,'VIEW ONLY Dashboard'!A23,'Product In'!I:I) -> 0 | C23: =B23/SUM($B$21:$B$41) -> 0 | D23: Market/Distributor/Supplier | E23: =SUMIF('Product In'!D:D,'VIEW ONLY Dashboard'!D23,'Product In'!I:I) -> 0
A24: Fats & Oils | B24: =SUMIF('Product In'!E:E,'VIEW ONLY Dashboard'!A24,'Product In'!I:I) -> 0 | C24: =B24/SUM($B$21:$B$41) -> 0 | D24: Manufacturer/Processor | E24: =SUMIF('Product In'!D:D,'VIEW ONLY Dashboard'!D24,'Product In'!I:I) -> 6770
A25: Fruits & Vegetables | B25: =SUMIF('Product In'!E:E,'VIEW ONLY Dashboard'!A25,'Product In'!I:I) -> 6807.3 | C25: =B25/SUM($B$21:$B$41) -> 0.88214027 | D25: Retailer | E25: =SUMIF('Product In'!D:D,'VIEW ONLY Dashboard'!D25,'Product In'!I:I) -> 938.2
A26: Grains/Grain Products | B26: =SUMIF('Product In'!E:E,'VIEW ONLY Dashboard'!A26,'Product In'!I:I) -> 629 | C26: =B26/SUM($B$21:$B$41) -> 0.081510471 | D26: Packer/Shipper/Wholesaler | E26: =SUMIF('Product In'!D:D,'VIEW ONLY Dashboard'!D26,'Product In'!I:I) -> 0
A27: Prepared Foods | B27: =SUMIF('Product In'!E:E,'VIEW ONLY Dashboard'!A27,'Product In'!I:I) -> 2.5 | C27: =B27/SUM($B$21:$B$41) -> 0.00032396848 | D27: Supply Chain Intermediaries | E27: =SUMIF('Product In'!D:D,'VIEW ONLY Dashboard'!D27,'Product In'!I:I) -> 0
A28: Protein - Animal Based | B28: =SUMIF('Product In'!E:E,'VIEW ONLY Dashboard'!A28,'Product In'!I:I) -> 4 | C28: =B28/SUM($B$21:$B$41) -> 0.00051834957 | D28: Food Donation Drive | E28: =SUMIF('Product In'!D:D,'VIEW ONLY Dashboard'!D28,'Product In'!I:I) -> 8.6
A29: Processed Cereals/Cereal Products | B29: =SUMIF('Product In'!E:E,'VIEW ONLY Dashboard'!A29,'Product In'!I:I) -> 16 | C29: =B29/SUM($B$21:$B$41) -> 0.0020733983
A30: Ready-To-Eat Savouries | B30: =SUMIF('Product In'!E:E,'VIEW ONLY Dashboard'!A30,'Product In'!I:I) -> 56.85 | C30: =B30/SUM($B$21:$B$41) -> 0.0073670433
A31: Sauces/Condiments/Seasonings | B31: =SUMIF('Product In'!E:E,'VIEW ONLY Dashboard'!A31,'Product In'!I:I) -> 1.2 | C31: =B31/SUM($B$21:$B$41) -> 0.00015550487
A32: Special Nutritional Uses | B32: =SUMIF('Product In'!E:E,'VIEW ONLY Dashboard'!A32,'Product In'!I:I) -> 0 | C32: =B32/SUM($B$21:$B$41) -> 0
A33: Sweeteners | B33: =SUMIF('Product In'!E:E,'VIEW ONLY Dashboard'!A33,'Product In'!I:I) -> 0 | C33: =B33/SUM($B$21:$B$41) -> 0 | F33: CHECKS (All numbers should be the same)
A34: Beverage - Water | B34: =SUMIF('Product In'!E:E,'VIEW ONLY Dashboard'!A34,'Product In'!I:I) -> 0 | C34: =B34/SUM($B$21:$B$41) -> 0 | F34: TOTAL KG FROM PRODUCT CATEGORY RECEIVED | G34: =SUM(B21:B41) -> 7716.8
A35: Beverage - Juices/Coffee/Tea | B35: =SUMIF('Product In'!E:E,'VIEW ONLY Dashboard'!A35,'Product In'!I:I) -> 3.15 | C35: =B35/SUM($B$21:$B$41) -> 0.00040820029 | F35: TOTAL KG FROM DONOR CATEGORY | G35: =SUM(E21:E28) -> 7716.8
A36: Beverage - Sweetened Beverages | B36: =SUMIF('Product In'!E:E,'VIEW ONLY Dashboard'!A36,'Product In'!I:I) -> 5.95 | C36: =B36/SUM($B$21:$B$41) -> 0.00077104499 | F36: TOTAL KG FROM DONATED/PURCHASED | G36: =SUM(G21:G22) -> 7716.8
A37: Non-Food - Personal Hygiene | B37: =SUMIF('Product In'!E:E,'VIEW ONLY Dashboard'!A37,'Product In'!I:I) -> 2.7 | C37: =B37/SUM($B$21:$B$41) -> 0.00034988596
A38: Non-Food - Cleaning Products | B38: =SUMIF('Product In'!E:E,'VIEW ONLY Dashboard'!A38,'Product In'!I:I) -> 0 | C38: =B38/SUM($B$21:$B$41) -> 0 | F38: CHECKS (All numbers should be the same)
A39: Non-Food - Baby Products | B39: =SUMIF('Product In'!E:E,'VIEW ONLY Dashboard'!A39,'Product In'!I:I) -> 0 | C39: =B39/SUM($B$21:$B$41) -> 0 | F39: TOTAL KG FROM PRODUCT CATEGORY DISTRIBUTED | G39: =SUM(B62:B82) -> 7717.96
A40: Non-Food - Others | B40: =SUMIF('Product In'!E:E,'VIEW ONLY Dashboard'!A40,'Product In'!I:I) -> 133.35 | C40: =B40/SUM($B$21:$B$41) -> 0.017280479 | F40: TOTAL KG FROM DONOR CATEGORY | G40: =SUM(E62:E202) -> 4120.7
A41: Non-Food - Pet Food | B41: =SUMIF('Product In'!E:E,'VIEW ONLY Dashboard'!A41,'Product In'!I:I) -> 26.6 | C41: =B41/SUM($B$21:$B$41) -> 0.0034470247 | F41: Any differences in the numbers means there are errors in Product In or Product Out pages
A42: TOTAL FOOD RECEIVED | B42: =SUM(B21:B36) -> 7554.15
A43: TOTAL NON-FOOD RECEIVED | B43: =SUM(B37:B41) -> 162.65
A45: Distribution
H47: FOR GFN MONTHLY REPORTING
H49: Total Number of Kilos Distributed | J49: =SUM(B83) -> 7628.31
H50: Total Number of Agencies Served | J50: 23
H51: Total Number of People Served | J51: =SUM(F62:F84) -> #N/A
H52: Kilograms Dairy Distributed | J52: =B64 -> 0
H53: Kilograms Fruit and Vegetable Distributed | J53: =B66 -> 6683.75
H54: Kilograms Grains Distributed | J54: =B67 -> 675.45
H55: Kiligrams Animal Proteins Distributed | J55: =B69 -> 0.2
A61: Product Category | B61: Quantity | C61: % of Total | D61: Beneficiary Agencies Served | E61: KG Received | F61: People Served
A62: Bakery | B62: =SUMIF('Product Out'!E:E,'VIEW ONLY Dashboard'!A62,'Product Out'!H:H) -> 37.6 | C62: =B62/SUM($B$62:$B$82) -> 0.0048717537 | D62: 4Freedom | E62: =SUMIF('Product Out'!C:C,D62,'Product Out'!H:H) -> 0 | F62: =VLOOKUP(D62,'Beneficiary Agency Database'!A:H,8,FALSE) -> #N/A
A63: Confectionary | B63: =SUMIF('Product Out'!E:E,'VIEW ONLY Dashboard'!A63,'Product Out'!H:H) -> 0.75 | C63: =B63/SUM($B$62:$B$82) -> 9.7175938e-05 | D63: ABSNET | E63: =SUMIF('Product Out'!C:C,D63,'Product Out'!H:H) -> 33.8 | F63: =VLOOKUP(D63,'Beneficiary Agency Database'!A:H,8,FALSE) -> 100
A64: Dairy | B64: =SUMIF('Product Out'!E:E,'VIEW ONLY Dashboard'!A64,'Product Out'!H:H) -> 0 | C64: =B64/SUM($B$62:$B$82) -> 0 | D64: NGO - Angat Semblante Helping Hands inc. | E64: =SUMIF('Product Out'!C:C,D64,'Product Out'!H:H) -> 309.8 | F64: =VLOOKUP(D64,'Beneficiary Agency Database'!A:H,8,FALSE) -> 400
...

Sheet VIEW ONLY Realtime Inventory
A1: Food Bank | B1: Cebu Food Bank | D1: DO NOT EDIT THIS SHEET. NUMBERS ARE AUTOMATICALLY DRAWN FROM "PRODUCT IN" AND "PRODUCT OUT".
A2: Year | B2: 2024
A4: Realtime Inventory | B4: Stocks on hand (kg)
A5: Bakery | B5: =SUMIF('Product In'!E:E,'VIEW ONLY Realtime Inventory'!A5,'Product In'!I:I)-SUMIF('Product Out'!D:D,'VIEW ONLY Realtime Inventory'!A5,'Product Out'!H:H) -> 20.9
A6: Beverage - Juices/Coffee/Tea | B6: =SUMIF('Product In'!E:E,'VIEW ONLY Realtime Inventory'!A6,'Product In'!I:I)-SUMIF('Product Out'!D:D,'VIEW ONLY Realtime Inventory'!A6,'Product Out'!H:H) -> 3.15
A7: Beverage - Sweetened Beverages | B7: =SUMIF('Product In'!E:E,'VIEW ONLY Realtime Inventory'!A7,'Product In'!I:I)-SUMIF('Product Out'!D:D,'VIEW ONLY Realtime Inventory'!A7,'Product Out'!H:H) -> 5.95
A8: Beverage - Water | B8: =SUMIF('Product In'!E:E,'VIEW ONLY Realtime Inventory'!A8,'Product In'!I:I)-SUMIF('Product Out'!D:D,'VIEW ONLY Realtime Inventory'!A8,'Product Out'!H:H) -> 0
A9: Confectionary | B9: =SUMIF('Product In'!E:E,'VIEW ONLY Realtime Inventory'!A9,'Product In'!I:I)-SUMIF('Product Out'!D:D,'VIEW ONLY Realtime Inventory'!A9,'Product Out'!H:H) -> 7.3
A10: Dairy | B10: =SUMIF('Product In'!E:E,'VIEW ONLY Realtime Inventory'!A10,'Product In'!I:I)-SUMIF('Product Out'!D:D,'VIEW ONLY Realtime Inventory'!A10,'Product Out'!H:H) -> 0
A11: Fats & Oils | B11: =SUMIF('Product In'!E:E,'VIEW ONLY Realtime Inventory'!A11,'Product In'!I:I)-SUMIF('Product Out'!D:D,'VIEW ONLY Realtime Inventory'!A11,'Product Out'!H:H) -> 0
A12: Fruits & Vegetables | B12: =SUMIF('Product In'!E:E,'VIEW ONLY Realtime Inventory'!A12,'Product In'!I:I)-SUMIF('Product Out'!D:D,'VIEW ONLY Realtime Inventory'!A12,'Product Out'!H:H) -> 6807.3
A13: Grains/Grain Products | B13: =SUMIF('Product In'!E:E,'VIEW ONLY Realtime Inventory'!A13,'Product In'!I:I)-SUMIF('Product Out'!D:D,'VIEW ONLY Realtime Inventory'!A13,'Product Out'!H:H) -> 629
A14: Non-Food - Baby Products | B14: =SUMIF('Product In'!E:E,'VIEW ONLY Realtime Inventory'!A14,'Product In'!I:I)-SUMIF('Product Out'!D:D,'VIEW ONLY Realtime Inventory'!A14,'Product Out'!H:H) -> 0
A15: Non-Food - Cleaning Products | B15: =SUMIF('Product In'!E:E,'VIEW ONLY Realtime Inventory'!A15,'Product In'!I:I)-SUMIF('Product Out'!D:D,'VIEW ONLY Realtime Inventory'!A15,'Product Out'!H:H) -> 0
A16: Non-Food - Others | B16: =SUMIF('Product In'!E:E,'VIEW ONLY Realtime Inventory'!A16,'Product In'!I:I)-SUMIF('Product Out'!D:D,'VIEW ONLY Realtime Inventory'!A16,'Product Out'!H:H) -> 133.35
... A24: Sweeteners | B24: =SUMIF('Product In'!E:E,'VIEW ONLY Realtime Inventory'!A24,'Product In'!I:I)-SUMIF('Product Out'!D:D,'VIEW ONLY Realtime Inventory'!A24,'Product Out'!H:H) -> 0
A26: Total inventory by weight: | B26: =SUM(B5:B23) -> 7690.2

Sheet Beneficiary Agency Database
A1: Food Bank | B1: Cebu Food Bank | D1: Staff in charge | E1: Nichole
A2: Year | B2: 2024 | D2: Last updated | E2: 45627
A4: Beneficiary Agency Name - Add any new beneficiary agencies to this list | B4: Beneficiary Agency Category - Assign category to every beneficiary agency | C4: Person in charge | D4: Telephone Number | E4: Address | F4: Email | G4: Last Update of Information / Audit | H4: Total number of individuals served | I4: # of Male, under 18 | J4: # of Male, 18 to 60 | K4: # of Male, 60+ | L4: # of Female, under 18 | M4: # of Female, 18 to 60 | N4: # of Female, 60+
A5: ABSNET | B5: Mixed: offering a combinationof multiple services/programslisted above. | H5: 100
A6: LGU - Barangay Medellin | B6: Mixed: offering a combinationof multiple services/programslisted above. | H6: 100
A7: LGU - Barangay Basak | B7: Mixed: offering a combinationof multiple services/programslisted above. | H7: 1100
A8: LGU - Barangay Bacayan | B8: Mixed: offering a combinationof multiple services/programslisted above. | D8: 09618158717 | E8: Brgy. Bacayan Tlamban, Cebu City | H8: 200
A9: LGU - Barangay Basak | B9: Mixed: offering a combinationof multiple services/programslisted above. | H9: 1100
A10: LGU - Barangay Cambaro | B10: Mixed: offering a combinationof multiple services/programslisted above. | H10: 1000
A11: LGU - Barangay Centro | B11: Mixed: offering a combinationof multiple services/programslisted above. | H11: 600
A12: LGU - Barangay Guizo | B12: Mixed: offering a combinationof multiple services/programslisted above. | H12: 600
A13: LGU - Barangay Jagobiao | B13: Mixed: offering a combinationof multiple services/programslisted above. | H13: 1000
A14: LGU - Barangay Labogon | B14: Mixed: offering a combinationof multiple services/programslisted above. | H14: 600
A15: LGU - Barangay Looc | B15: Mixed: offering a combinationof multiple services/programslisted above. | H15: 1300
A16: LGU - Barangay Maguikay | B16: Mixed: offering a combinationof multiple services/programslisted above. | H16: 500
A17: LGU - Barangay Opao | B17: Mixed: offering a combinationof multiple services/programslisted above. | H17: 500
A18: LGU - Barangay Paknaan | B18: Mixed: offering a combinationof multiple services/programslisted above. | H18: 500
A19: LGU - Barangay Subangdako | B19: Mixed: offering a combinationof multiple services/programslisted above. | H19: 500
A20: LGU - Barangay Tabok | B20: Health/Medical: clinics,hospitals, nutrition hubs | H20: 700
A21: LGU - Barangay Tinago c/o Phil. Navy | B21: Mixed: offering a combinationof multiple services/programslisted above. | C21: Maam Delia | E21: Barangay Tinago Pier 3, Cebu City | H21: 200
A22: LGU - Barangay Umapad | B22: Mixed: offering a combinationof multiple services/programslisted above. | H22: 600
A23: LGU - Barili | B23: Mixed: offering a combinationof multiple services/programslisted above. | H23: 100
A24: LGU - BARING CARMEN | B24: Mixed: offering a combinationof multiple services/programslisted above. | D24: 09069219387 | E24: BARING CARMEN CEBU | H24: 200
A25: LGU - Danao | B25: Mixed: offering a combinationof multiple services/programslisted above. | H25: 200
A26: LGU - GMAC PHO | B26: Mixed: offering a combinationof multiple services/programslisted above. | H26: 400
A27: LGU - GUIZO MANDAUE | B27: Mixed: offering a combinationof multiple services/programslisted above. | D27: 0920604000 | E27: GUIZO MANDAUE CITY | H27: 200
A28: LGU - Municipality of Tabuelan | B28: Mixed: offering a combinationof multiple services/programslisted above. | C28: Ivar Sena | D28: 09198230397 | E28: Tabuelan, Cebu City | H28: 200
A29: LGU - Municipality of Tuburan | B29: Mixed: offering a combinationof multiple services/programslisted above. | C29: Lloyd Romero | D29: 09955649582 | E29: Tuburan, Cebu City | H29: 200
A30: LGU - Pinamungahan | B30: Mixed: offering a combinationof multiple services/programslisted above. | H30: 100
A31: LGU - Sto. Nino Malabuyoc, Cebu | B31: Mixed: offering a combinationof multiple services/programslisted above. | C31: Junjun Ponce Bequilla | D31: 09616542050 | E31: Malabuyoc, Cebu City | H31: 100
A32: LGU -Carcar | B32: Mixed: offering a combinationof multiple services/programslisted above. | H32: 100
A33: NGO - 4Freedom | B33: Mixed: offering a combinationof multiple services/programslisted above. | H33: 100
A34: NGO - Angat Semblante Helping Hands inc. | B34: Shelter: temporary housingsituation, homeless shelter,abused women’s shelter,group homes. | C34: Tarratheci Sembante | D34: 9237398973 | E34: Nangka ConsolacionCebu | H34: 400
A35: NGO - Angelika | B35: Mixed: offering a combinationof multiple services/programslisted above. | H35: 100
A36: NGO - Bukas Palad Foundation | B36: Mixed: offering a combinationof multiple services/programslisted above. | H36: 500
A37: NGO - Cebu Equalizer | B37: Mixed: offering a combinationof multiple services/programslisted above. | C37: Genevic Jumawan Suico | D37: 09363795185 | E37: Toledo, Cebu City | H37: 1200
A38: NGO - Children of Cebu | B38: Child-specific program:school, daycare, group home,orphanage, summer camp. | C38: Keishza | D38: 09513644534 | E38: Cebu City | H38: 250
A39: NGO - Cure Foundation | B39: Child-specific program:school, daycare, group home,orphanage, summer camp. | C39: Sir Bart | D39: 09106569442 | E39: Pinamungajan Cebu | H39: 300
A40: NGO - DICE Children of Asia | B40: Child-specific program:school, daycare, group home,orphanage, summer camp. | C40: Maam Cherryl | D40: 09955152197 | E40: Ermita, Cebu City | H40: 100
A41: NGO - Down Syndrome Association | B41: Mixed: offering a combinationof multiple services/programslisted above. | H41: 50
...

Sheet Food Donor Database
A1: Food Bank | B1: Cebu Food Bank | D1: Staff in charge | E1: Claire
A2: Year | B2: 2024 | D2: Last updated | E2: 45627
A4: Donor - Add any new donor companies to this list | B4: Donor Category - Assign donor category to every donor company | C4: Person in charge | D4: Telephone Number | E4: Address | F4: Email
A5: Mondelez | B5: Manufacturer/Processor | C5: c/o RAH
A6: San Miguel | B6: Manufacturer/Processor | C6: c/o RAH
A7: Del Monte | B7: Manufacturer/Processor | C7: c/o RAH
A8: Rise Against Hunger Philippines | B8: Others | C8: Iris Maligat
A9: The Purefoods Hormel Co Inc | B9: Manufacturer/Processor | C9: c/o RAH
A10: Magnolia Phil | B10: Manufacturer/Processor | C10: c/o RAH
A11: Foodpanda | B11: Retailer | C11: c/o RAH
A12: DALAGUETE FARMERS | B12: Agriculture | C12: HARLENE | E12: DALAGUETE CEBU
A13: BigBlue | B13: Supply Chain Intermediaries
A14: ROBINSONS TABUNOK | B14: Retailer | C14: Louie Barro | D14: 9988466820
A15: ROBINSONS FUENTE | B15: Retailer | C15: Razilee Tan | D15: 9176585351
A16: ROBINSONS PUEBLO | B16: Retailer | C16: Jerrylen | D16: 9950221008
A17: ROBINSONS BASELINE | B17: Retailer | C17: Katherine Galgo | D17: 9988418442
A18: ROBINSON MINGLANILLA | B18: Retailer | C18: Michelle Perez | D18: 9190894894
A19: ROBINSONS TALAMBAN | B19: Retailer | C19: Reah Pioquinto | D19: 9190713425
A20: ROBINSONS BANILAD | B20: Retailer | C20: Marites Aloro | D20: 9164543955
A21: ROBINSONS MACTAN | B21: Retailer | C21: Dhanie Ditasolo | D21: 9988465099
A22: ROBINSONS TALISAY | B22: Retailer | C22: Benjamin Dalmacion | D22: 9988466801
A23: ROBINSONS GUADALUPE | B23: Retailer | C23: Leslie Macalolooy | D23: 9913188964
A24: The SleepCompany | B24: Manufacturer/Processor | C24: Emma Sleep
A25: PL INSURANCE SERVICES | B25: Food Donation Drive
A26: Virginia | B26: Manufacturer/Processor
A27: Radisson Blu | B27: Retailer

Sheet Product In
A1: Food Bank | B1: Cebu Food Bank | D1: Staff in charge | E1: Ace
A2: Year | B2: 2024 | D2: Last updated | E2: 45658
A4: Date Distributed DD-MMM-YY | B4: Month (dropdown) | C4: Donor | D4: Donor Category (automatically filled) | E4: Product Category (dropdown) | F4: Product Name | G4: Quantity | H4: Unit (Packet/Bottle/Pieces) | I4: Total Weight | J4: Expiry Date | K4: Remaining days to expiry | L4: Donated/Purchased (dropdown) | M4: Value
A5: 45656 | B5: December | C5: ROBINSONS BANILAD | D5: =VLOOKUP(C5,'Food Donor Database'!A:B,2,FALSE) -> Retailer | E5: Processed Cereals/Cereal Products | F5: NB Cereal Corn Sweet 600g | G5: 4 | H5: bag | I5: 2.4 | J5: 45661 | K5: =DAYS360(A5,J5,FALSE) -> 4 | L5: Donated | M5: 1330
A6: 45656 | B6: December | C6: ROBINSONS BANILAD | D6: =VLOOKUP(C6,'Food Donor Database'!A:B,2,FALSE) -> Retailer | E6: Fruits & Vegetables | F6: NB Roasted Cashewnut 650g | G6: 25 | H6: bottle | I6: 20 | J6: 45664 | K6: =DAYS360(A6,J6,FALSE) -> 7 | L6: Donated | M6: 33500
A7: 45656 | B7: December | C7: ROBINSONS BANILAD | D7: =VLOOKUP(C7,'Food Donor Database'!A:B,2,FALSE) -> Retailer | E7: Ready-To-Eat Savouries | F7: Cheez It Cheese 25g | G7: 82 | H7: piece | I7: 2.85 | J7: 45665 | K7: =DAYS360(A7,J7,FALSE) -> 8 | L7: Donated | M7: 574
A8: 45656 | B8: December | C8: ROBINSONS BANILAD | D8: =VLOOKUP(C8,'Food Donor Database'!A:B,2,FALSE) -> Retailer | E8: Ready-To-Eat Savouries | F8: Peewee Pizza 95g | G8: 75 | H8: piece | I8: 7.5 | J8: 45667 | K8: =DAYS360(A8,J8,FALSE) -> 10 | L8: Donated | M8: 1893.75
A9: 45656 | B9: December | C9: ROBINSONS BANILAD | D9: =VLOOKUP(C9,'Food Donor Database'!A:B,2,FALSE) -> Retailer | E9: Ready-To-Eat Savouries | F9: Okeji Tempura 100g | G9: 25 | H9: piece | I9: 3.45 | J9: 45668 | K9: =DAYS360(A9,J9,FALSE) -> 11 | L9: Donated | M9: 631.25
A10: 45656 | B10: December | C10: ROBINSONS BANILAD | D10: =VLOOKUP(C10,'Food Donor Database'!A:B,2,FALSE) -> Retailer | E10: Non-Food - Others | F10: OLS Toys | G10: 35 | H10: box | I10: 3.5 | J10: N/A | K10: N/A | L10: Donated | M10: 3491.25
A11: 45649 | B11: December | C11: PL INSURANCE SERVICES | D11: =VLOOKUP(C11,'Food Donor Database'!A:B,2,FALSE) -> Food Donation Drive | E11: Bakery | F11: Rebisco Wafertime Rich Cream | G11: 10 | H11: bag | I11: 3 | J11: 45680 | K11: =DAYS360(A11,J11,FALSE) -> 30 | L11: Donated | M11: 0
A12: 45649 | B12: December | C12: PL INSURANCE SERVICES | D12: =VLOOKUP(C12,'Food Donor Database'!A:B,2,FALSE) -> Food Donation Drive | E12: Bakery | F12: Hanzel Milky Strawberry Sandwich | G12: 16 | H12: bag | I12: 5.6 | J12: 45654 | K12: =DAYS360(A12,J12,FALSE) -> 5 | L12: Donated | M12: 0
A13: 45645 | B13: December | C13: Virginia | D13: =VLOOKUP(C13,'Food Donor Database'!A:B,2,FALSE) -> Manufacturer/Processor | E13: Fruits & Vegetables | F13: Happy Farm Sweet Corn on the Cob | G13: 434 | H13: box | I13: 6510 | J13: 45654 | K13: =DAYS360(A13,J13,FALSE) -> 9 | L13: Donated | M13: 0
A14: 45635 | B14: December | C14: Virginia | D14: =VLOOKUP(C14,'Food Donor Database'!A:B,2,FALSE) -> Manufacturer/Processor | E14: Fruits & Vegetables | F14: Happy Farm Sweet Corn Frozen Whole Kernel 500g | G14: 20 | H14: case | I14: 260 | J14: 45652 | K14: =DAYS360(A14,J14,FALSE) -> 17 | L14: Donated | M14: 0
A15: 45632 | B15: December | C15: ROBINSONS BANILAD | D15: =VLOOKUP(C15,'Food Donor Database'!A:B,2,FALSE) -> Retailer | E15: Bakery | F15: Certera Butter Toasted | G15: 11 | H15: bag | I15: 1.65 | J15: 45639 | K15: =DAYS360(A15,J15,FALSE) -> 7 | L15: Donated | M15: 803
A16: 45632 | B16: December | C16: ROBINSONS BANILAD | D16: =VLOOKUP(C16,'Food Donor Database'!A:B,2,FALSE) -> Retailer | E16: Ready-To-Eat Savouries | F16: Loaded Cheese 32g | G16: 164 | H16: piece | I16: 6.35 | J16: 45639 | K16: =DAYS360(A16,J16,FALSE) -> 7 | L16: Donated | M16: 1394
A17: 45632 | B17: December | C17: ROBINSONS BANILAD | D17: =VLOOKUP(C17,'Food Donor Database'!A:B,2,FALSE) -> Retailer | E17: Ready-To-Eat Savouries | F17: Peewee BBQ 25g | G17: 139 | H17: piece | I17: 4.6 | J17: 45639 | K17: =DAYS360(A17,J17,FALSE) -> 7 | L17: Donated | M17: 973
A18: 45632 | B18: December | C18: ROBINSONS BANILAD | D18: =VLOOKUP(C18,'Food Donor Database'!A:B,2,FALSE) -> Retailer | E18: Confectionary | F18: Hinam is Pyramid Yemma Ube 15s | G18: 11 | H18: box | I18: 3.3 | J18: 45641 | K18: =DAYS360(A18,J18,FALSE) -> 9 | L18: Donated | M18: 1848
A19: 45632 | B19: December | C19: ROBINSONS BANILAD | D19: =VLOOKUP(C19,'Food Donor Database'!A:B,2,FALSE) -> Retailer | E19: Fruits & Vegetables | F19: Heritage Raw Cashew 250g | G19: 3 | H19: bag | I19: 0.75 | J19: 45641 | K19: =DAYS360(A19,J19,FALSE) -> 9 | L19: Donated | M19: 939
A20: 45632 | B20: December | C20: ROBINSONS BANILAD | D20: =VLOOKUP(C20,'Food Donor Database'!A:B,2,FALSE) -> Retailer | E20: Fruits & Vegetables | F20: Heritage Whole Almonds 500g | G20: 1 | H20: bag | I20: 0.5 | J20: 45643 | K20: =DAYS360(A20,J20,FALSE) -> 11 | L20: Donated | M20: 670
A21: 45632 | B21: December | C21: ROBINSONS BANILAD | D21: =VLOOKUP(C21,'Food Donor Database'!A:B,2,FALSE) -> Retailer | E21: Ready-To-Eat Savouries | F21: Richeese Big Roll 300g | G21: 1 | H21: can | I21: 0.5 | J21: 45645 | K21: =DAYS360(A21,J21,FALSE) -> 13 | L21: Donated | M21: 160
A22: 45632 | B22: December | C22: ROBINSONS BANILAD | D22: =VLOOKUP(C22,'Food Donor Database'!A:B,2,FALSE) -> Retailer | E22: Ready-To-Eat Savouries | F22: Lorenz Naturals Balsimic Vinegar 100g | G22: 13 | H22: piece | I22: 1.3 | J22: 45637 | K22: =DAYS360(A22,J22,FALSE) -> 5 | L22: Donated | M22: 1365
... A45: 45632 | B45: December | C45: ROBINSONS BANILAD | D45: =VLOOKUP(C45,'Food Donor Database'!A:B,2,FALSE) -> Retailer | E45: Bakery | F45: Robinsons Pacencia 90g | G45: 66 | H45: packet | I45: 6.8 | J45: 45647 | K45: =DAYS360(A45,J45,FALSE) -> 15 | L45: Donated | M45: 2079
A46: 45631 | B46: December | C46: ROBINSONS TABUNOK | D46: =VLOOKUP(C46,'Food Donor Database'!A:B,2,FALSE) -> Retailer | E46: Non-Food - Pet Food | F46: Mix Dog food | G46: 1 | H46: sack | I46: 7.2 | J46: N/A | K46: N/A | L46: Donated | M46: 0
A47: 45631 | B47: December | C47: ROBINSONS TABUNOK | D47: =VLOOKUP(C47,'Food Donor Database'!A:B,2,FALSE) -> Retailer | E47: Grains/Grain Products | F47: Mix Rice | G47: 1 | H47: sack | I47: 25.1 | J47: N/A | K47: N/A | L47: Donated | M47: 0
A48: 45631 | B48: December | C48: ROBINSONS TABUNOK | D48: =VLOOKUP(C48,'Food Donor Database'!A:B,2,FALSE) -> Retailer | E48: Grains/Grain Products | F48: Mix Rice | G48: 1 | H48: sack | I48: 23.15 | J48: N/A | K48: N/A | L48: Donated | M48: 0
A49: 45631 | B49: December | C49: ROBINSONS TABUNOK | D49: =VLOOKUP(C49,'Food Donor Database'!A:B,2,FALSE) -> Retailer | E49: Grains/Grain Products | F49: Pan Pan Jasmine 5kg | G49: 1 | H49: sack | I49: 5 | J49: N/A | K49: N/A | L49: Donated | M49: 0
A50: 45631 | B50: December | C50: ROBINSONS TABUNOK | D50: =VLOOKUP(C50,'Food Donor Database'!A:B,2,FALSE) -> Retailer | E50: Grains/Grain Products | F50: Robinson's Intan 10kg | G50: 6 | H50: sack | I50: 60 | J50: N/A | K50: N/A | L50: Donated | M50: 0
A51: 45631 | B51: December | C51: ROBINSONS TABUNOK | D51: =VLOOKUP(C51,'Food Donor Database'!A:B,2,FALSE) -> Retailer | E51: Grains/Grain Products | F51: Robinson's Whole Grain 10kg | G51: 2 | H51: sack | I51: 20 | J51: 45572 | K51: =DAYS360(A51,J51,FALSE) -> -58 | L51: Donated | M51: 0
A52: 45631 | B52: December | C52: ROBINSONS TABUNOK | D52: =VLOOKUP(C52,'Food Donor Database'!A:B,2,FALSE) -> Retailer | E52: Grains/Grain Products | F52: Robinson's Dinorado 10kg | G52: 1 | H52: sack | I52: 10 | J52: 45580 | K52: =DAYS360(A52,J52,FALSE) -> -50 | L52: Donated | M52: 0
A53: 45631 | B53: December | C53: ROBINSONS TABUNOK | D53: =VLOOKUP(C53,'Food Donor Database'!A:B,2,FALSE) -> Retailer | E53: Grains/Grain Products | F53: Farmer's Choice Dinorado 10kg | G53: 4 | H53: sack | I53: 40 | J53: 45724 | K53: =DAYS360(A53,J53,FALSE) -> 93 | L53: Donated | M53: 0
A54: 45631 | B54: December | C54: ROBINSONS TABUNOK | D54: =VLOOKUP(C54,'Food Donor Database'!A:B,2,FALSE) -> Retailer | E54: Grains/Grain Products | F54: Robinson's Intan 5kg | G54: 2 | H54: sack | I54: 10 | J54: 45727 | K54: =DAYS360(A54,J54,FALSE) -> 96 | L54: Donated | M54: 0
A55: 45631 | B55: December | C55: ROBINSONS TABUNOK | D55: =VLOOKUP(C55,'Food Donor Database'!A:B,2,FALSE) -> Retailer | E55: Grains/Grain Products | F55: Farmboy Long Grain Rice 10kg | G55: 3 | H55: sack | I55: 30 | J55: 45769 | K55: =DAYS360(A55,J55,FALSE) -> 137 | L55: Donated | M55: 0
A56: 45631 | B56: December | C56: ROBINSONS TABUNOK | D56: =VLOOKUP(C56,'Food Donor Database'!A:B,2,FALSE) -> Retailer | E56: Grains/Grain Products | F56: Farmer's Choice Sinandomeng 10kg | G56: 4 | H56: sack | I56: 40 | J56: 45778 | K56: =DAYS360(A56,J56,FALSE) -> 146 | L56: Donated | M56: 0
A57: 45631 | B57: December | C57: ROBINSONS TABUNOK | D57: =VLOOKUP(C57,'Food Donor Database'!A:B,2,FALSE) -> Retailer | E57: Non-Food - Pet Food | F57: Vitapet Kitten Fish&Egg 480g | G57: 2 | H57: sack | I57: 0.8 | J57: 45787 | K57: =DAYS360(A57,J57,FALSE) -> 155 | L57: Donated | M57: 0
A58: 45631 | B58: December | C58: ROBINSONS TABUNOK | D58: =VLOOKUP(C58,'Food Donor Database'!A:B,2,FALSE) -> Retailer | E58: Grains/Grain Products | F58: Farmer's Choice Whole Grain 10kg | G58: 3 | H58: sack | I58: 30 | J58: 45795 | K58: =DAYS360(A58,J58,FALSE) -> 163 | L58: Donated | M58: 0
A59: 45631 | B59: December | C59: ROBINSONS TABUNOK | D59: =VLOOKUP(C59,'Food Donor Database'!A:B,2,FALSE) -> Retailer | E59: Grains/Grain Products | F59: Robinson's Jasmine 10kg | G59: 3 | H59: sack | I59: 30 | J59: 45836 | K59: =DAYS360(A59,J59,FALSE) -> 203 | L59: Donated | M59: 0
A60: 45631 | B60: December | C60: ROBINSONS TABUNOK | D60: =VLOOKUP(C60,'Food Donor Database'!A:B,2,FALSE) -> Retailer | E60: Grains/Grain Products | F60: Harvester's Dinorado 10kg | G60: 2 | H60: sack | I60: 20 | J60: 45862 | K60: =DAYS360(A60,J60,FALSE) -> 229 | L60: Donated | M60: 0
A61: 45631 | B61: December | C61: ROBINSONS TABUNOK | D61: =VLOOKUP(C61,'Food Donor Database'!A:B,2,FALSE) -> Retailer | E61: Grains/Grain Products | F61: Harvester's Long Grain 5kg | G61: 5 | H61: sack | I61: 25 | J61: 45893 | K61: =DAYS360(A61,J61,FALSE) -> 259 | L61: Donated | M61: 0
A62: 45631 | B62: December | C62: ROBINSONS TABUNOK | D62: =VLOOKUP(C62,'Food Donor Database'!A:B,2,FALSE) -> Retailer | E62: Grains/Grain Products | F62: Robinson's Jasmine 5kg | G62: 7 | H62: sack | I62: 35 | J62: 45909 | K62: =DAYS360(A62,J62,FALSE) -> 274 | L62: Donated | M62: 0
A63: 45631 | B63: December | C63: ROBINSONS TABUNOK | D63: =VLOOKUP(C63,'Food Donor Database'!A:B,2,FALSE) -> Retailer | E63: Grains/Grain Products | F63: Robinson's Jasmine 2kg | G63: 1 | H63: sack | I63: 2 | J63: 45911 | K63: =DAYS360(A63,J63,FALSE) -> 276 | L63: Donated | M63: 0
...

Sheet Product Out
A1: Food Bank | B1: Cebu Food Bank | D1: Staff in charge | E1: Ace
A2: Year | B2: 2024 | D2: Last updated | E2: 45658
A4: Date Distributed DD-MMM-YY | B4: Month (dropdown) | C4: Beneficiary Agency | D4: Product Category (dropdown) | E4: Product Name | F4: Quantity | G4: Unit (Packet/Bottle/Pieces) | H4: Weight (kg)
A5: 45636 | B5: December | C5: NGO - 4Freedom | D5: Meal Pack | E5: Grains/Grain Products | F5: 1 | G5: box | H5: 15
A6: 45636 | B6: December | C6: NGO - 4Freedom | D6: Happy Farm Sweet Corn | E6: Fruits & Vegetables | F6: 24 | G6: case | H6: 12.75
A7: 45636 | B7: December | C7: NGO - 4Freedom | D7: Susu Kukis Vanilla | E7: Bakery | F7: 32 | G7: piece | H7: 2.05
A8: 45636 | B8: December | C8: NGO - 4Freedom | D8: Juju Choco snack biscuit | E8: Bakery | F8: 24 | G8: piece | H8: 1.5
A9: 45631 | B9: December | C9: ABSNET | D9: Emma Bed | E9: Non-Food - Others | F9: 1 | G9: box | H9: 33.8
A10: 45645 | B10: December | C10: NGO - Angat Semblante Helping Hands inc. | D10: Meal Pack | E10: Grains/Grain Products | F10: 1 | G10: box | H10: 15
A11: 45645 | B11: December | C11: NGO - Angat Semblante Helping Hands inc. | D11: Happy Farm Corn on the Cob | E11: Fruits & Vegetables | F11: 16 | G11: box | H11: 240
A12: 45645 | B12: December | C12: PASTORAL - Asilo dela Milagrosa | D12: Happy Farm Corn on the Cob | E12: Fruits & Vegetables | F12: 16 | G12: box | H12: 240
A13: 45645 | B13: December | C13: LGU - Barangay Basak | D13: Meal Pack | E13: Grains/Grain Products | F13: 1 | G13: box | H13: 15
A14: 45645 | B14: December | C14: LGU - Barangay Cambaro | D14: Happy farm Corn on the Cob | E14: Fruits & Vegetables | F14: 16 | G14: box | H14: 240
A15: 45645 | B15: December | C15: LGU - Barangay Centro | D15: Meal Pack | E15: Grains/Grain Products | F15: 1 | G15: box | H15: 15
A16: 45645 | B16: December | C16: LGU - Barangay Centro | D16: HAppy Farm Corn on the Cob | E16: Fruits & Vegetables | F16: 8 | G16: box | H16: 120
... A191: 45645 | B191: December | C191: LGU - Barangay Tabok | D191: Happy Farm Corn on the Cob | E191: Fruits & Vegetables | F191: 10 | G191: box | H191: 160

Sheet Do Not Edit
A1: Beneficiary Agency Category (do not add/change) | C1: Donor Category (do not add/change) | E1: Product Category (do not add/change) | F1: Examples | H1: Donated / Purchased (do not add/change) | J1: Month | L1: DO NOT EDIT THIS SHEET.
A2: Child-specific program:school, daycare, group home,orphanage, summer camp. | C2: Agriculture | E2: Bakery | F2: Bread, cakes, cookies. | H2: Donated | J2: January
A3: Congregate meal site:organizations that offer mealsto be eaten on-site but thebeneficiaries do not live there(for example, soup kitchens,community centers, drop-inprograms for seniors, etc.). | C3: Food Services | E3: Beverage - Juices/Coffee/Tea | F3: Juices, coﬀee, tea, nut or plant based and non- dairy. | H3: Purchased | J3: February
A4: Food pantry/foodshelf/grocery distribution:organization that providesfood and grocery productsdirectly to individuals for theiruse at home. | C4: Market/Distributor/Supplier | E4: Beverage - Sweetened Beverages | F4: Soda or sugary drinks (not plant-based juices). | J4: March
A5: Health/Medical: clinics,hospitals, nutrition hubs | C5: Manufacturer/Processor | E5: Beverage - Water | J5: April
A6: Mixed: offering a combinationof multiple services/programslisted above. | C6: Retailer | E6: Confectionary | F6: Sweets, ice cream, candies, sorbets, jams/jellies, sweetened condensed milk. | J6: May
A7: Others | C7: Packer/Shipper/Wholesaler | E7: Dairy | F7: Cheese/cheese products, paneer, yogurt, etc., including dairy beverages like milk and drinkable yogurt. Excluding plant-based beverages, dairy desserts, condensed milk, cream and ice creams. | J7: June
A8: Shelter: temporary housingsituation, homeless shelter,abused women’s shelter,group homes. | C8: Supply Chain Intermediaries | E8: Fats & Oils | F8: Cooking oil, cream, butter. | J8: July
C9: Food Donation Drive | E9: Fruits & Vegetables | F9: Including roots and tubers (for example, potato, cassava, yam) and salads. | J9: August
C10: Others | E10: Grains/Grain Products | F10: Rice, wheat, maize, sorghum, millet, etc., ﬂour of all kinds, barley, plain pasta/noodles (excluding ready-to-eat). | J10: September
E11: Non-Food - Baby Products | J11: October
E12: Non-Food - Cleaning Products | J12: November
E13: Non-Food - Others | J13: December
E14: Non-Food - Personal Hygiene
E15: Non-Food - Pet Food | F15: Cat food, dog food, etc
E16: Prepared Foods | F16: Ready-to-eat meals, soups, ready-to-eat instant noodles, frozen meals, catering
E17: Processed Cereals/Cereal Products | F17: Breakfast cereals, infant cereals, granola bars, breakfast bars, pancake mix.
E18: Protein - Animal Based | F18: Meat and meat products, ﬁsh and ﬁsh products, and eggs.
E19: Ready-To-Eat Savouries | F19: Crackers, chips.
E20: Sauces/Condiments/Seasonings
E21: Special Nutritional Uses | F21: Baby formula, nutrition supplement drinks like Ensure.
E22: Sweeteners
